[32m2025-05-02 16:04:26 +0900[0m - dagster - [34mDEBUG[0m - __ASSET_JOB - 16710006-8d35-4963-9923-58843b7fa16d - 123426 - LOGS_CAPTURED - Started capturing logs in process (pid: 123426).
[32m2025-05-02 16:04:26 +0900[0m - dagster - [34mDEBUG[0m - __ASSET_JOB - 16710006-8d35-4963-9923-58843b7fa16d - 123426 - processed_data - STEP_START - Started execution of step "processed_data".
[32m2025-05-02 16:04:26 +0900[0m - dagster - [34mERROR[0m - [31m__ASSET_JOB - 16710006-8d35-4963-9923-58843b7fa16d - 123426 - processed_data - STEP_FAILURE - Execution of step "processed_data" failed.

dagster._core.errors.DagsterExecutionStepExecutionError: Error occurred while executing op "processed_data"::

FileNotFoundError: [Errno 2] No such file or directory: '../data/sample_data.csv'

Stack Trace:
  File "/home/wnsgu/.pyenv/versions/3.11.0/envs/refund_env/lib/python3.11/site-packages/dagster/_core/execution/plan/utils.py", line 56, in op_execution_error_boundary
    yield
  File "/home/wnsgu/.pyenv/versions/3.11.0/envs/refund_env/lib/python3.11/site-packages/dagster/_utils/__init__.py", line 392, in iterate_with_context
    next_output = next(iterator)
                  ^^^^^^^^^^^^^^
  File "/home/wnsgu/.pyenv/versions/3.11.0/envs/refund_env/lib/python3.11/site-packages/dagster/_core/execution/plan/compute_generator.py", line 129, in _coerce_op_compute_fn_to_iterator
    result = invoke_compute_fn(
             ^^^^^^^^^^^^^^^^^^
  File "/home/wnsgu/.pyenv/versions/3.11.0/envs/refund_env/lib/python3.11/site-packages/dagster/_core/execution/plan/compute_generator.py", line 117, in invoke_compute_fn
    return fn(context, **args_to_pass) if context_arg_provided else fn(**args_to_pass)
                                                                    ^^^^^^^^^^^^^^^^^^
  File "/home/wnsgu/shinhan-life-test/dagster-quickstart/quickstart/assets.py", line 7, in processed_data
    df = pd.read_csv("../data/sample_data.csv")
         ^^^^^^^^^^^^^^^^^^^^^^^^^^^^^^^^^^^^^^
  File "/home/wnsgu/.pyenv/versions/3.11.0/envs/refund_env/lib/python3.11/site-packages/pandas/io/parsers/readers.py", line 1026, in read_csv
    return _read(filepath_or_buffer, kwds)
           ^^^^^^^^^^^^^^^^^^^^^^^^^^^^^^^
  File "/home/wnsgu/.pyenv/versions/3.11.0/envs/refund_env/lib/python3.11/site-packages/pandas/io/parsers/readers.py", line 620, in _read
    parser = TextFileReader(filepath_or_buffer, **kwds)
             ^^^^^^^^^^^^^^^^^^^^^^^^^^^^^^^^^^^^^^^^^^
  File "/home/wnsgu/.pyenv/versions/3.11.0/envs/refund_env/lib/python3.11/site-packages/pandas/io/parsers/readers.py", line 1620, in __init__
    self._engine = self._make_engine(f, self.engine)
                   ^^^^^^^^^^^^^^^^^^^^^^^^^^^^^^^^^
  File "/home/wnsgu/.pyenv/versions/3.11.0/envs/refund_env/lib/python3.11/site-packages/pandas/io/parsers/readers.py", line 1880, in _make_engine
    self.handles = get_handle(
                   ^^^^^^^^^^^
  File "/home/wnsgu/.pyenv/versions/3.11.0/envs/refund_env/lib/python3.11/site-packages/pandas/io/common.py", line 873, in get_handle
    handle = open(
             ^^^^^
[0m
